<?xml version="1.0"?>
<robot name="generated_robot">
  <mujoco >
    <compiler discardvisual="false"/>
  </mujoco>
  <link name="world"/>
  <joint name="world_to_body" type="fixed">
    <parent link="world"/>
    <child link="body"/>
    <origin xyz="0 0 1.0" rpy="0 0 0"/>
  </joint>
  <link name="body">
    <visual >
      <origin xyz="0 0 -0.5" rpy="0 0 0"/>
      <geometry >
        <cylinder radius="0.0800" length="1.0"/>
      </geometry>
      <material name="grey">
        <color rgba="0.5 0.5 0.5 1.0"/>
      </material>
    </visual>
    <inertial >
      <mass value="10.0"/>
      <inertia ixx="0.01" ixy="0" ixz="0" iyy="0.01" iyz="0" izz="0.01"/>
    </inertial>
  </link>
  <joint name="joint_0" type="revolute">
    <parent link="body"/>
    <child link="link_0"/>
    <origin xyz="0.0 0.0 0.3" rpy="0.0000 0.0000 0.0000"/>
    <axis xyz="0 0 1"/>
    <limit lower="-3.1416" upper="3.1730" effort="10" velocity="1"/>
  </joint>
  <link name="link_0">
    <inertial >
      <mass value="1.0"/>
      <inertia ixx="0.01" ixy="0" ixz="0" iyy="0.01" iyz="0" izz="0.01"/>
    </inertial>
  </link>
</robot>